<!-- author RinYoshida -->
<!-- email tororo1219@gmail.com -->

<mujoco model="inverted_pendulum">
  <option gravity="0 0 -9.81" integrator="RK4" timestep="0.01"/>

  <asset>
    <mesh name="stage_mesh" file="../meshes/stage.stl" scale="0.001 0.001 0.001"/>
    <mesh name="pole_mesh" file="../meshes/pole.stl" scale="0.001 0.001 0.001"/>
  </asset>

  <worldbody>
    <!-- <body name="origin" pos="0 0 0"> -->
    <!--   <geom name="y_axis" type="capsule" fromto="0 0 0 0 -0.5 0" size="0.01" rgba="0 1 0 1"/> -->
    <!-- </body> -->

    
    <!-- <body name="pole" pos="0 0 0"> -->
    <!--   <joint name="hinge1" type="hinge" pos="0 0 0.03" axis="0 1 0" range="-90 90" limited="true" damping="1.0"/> -->
    <!--   <inertial pos="0 0 0" mass="1.0" diaginertia="0.1 0.1 0.1"/> -->
    <!--   <geom type="mesh" mesh="pole_mesh" rgba="1 0 0 1"/> -->
    <!-- </body> -->
    
    <body name="stage" pos="0 0 0">
      <geom type="mesh" mesh="stage_mesh" rgba="1 0 0 1"/>
      <body name="pole" pos="0 0 0">
	<joint name="hinge1" type="hinge" pos="0 0 0.03" axis="0 1 0" range="-45 45" limited="true" damping="1.0"/>
	<inertial pos="0 0 0" mass="1.0" diaginertia="0.1 0.1 0.1"/>
	<geom type="mesh" mesh="pole_mesh" rgba="1 0 0 1"/>
      </body>
    </body>
 
 
    <!-- <body name="base" pos="0 0 0"> -->
    <!--   <geom type="box" size="0.2 0.2 0.02" rgba="0.6 0.6 0.6 1"/> -->
    <!--   <body name="pendulum" pos="0 0 0.02"> -->
    <!--     <joint name="hinge2" type="hinge" axis="0 1 0" range="-90 90" limited="true" damping="1.0"/> -->
    <!--     <inertial pos="0 0 0.4" mass="1.0" diaginertia="0.1 0.1 0.1"/> -->
    <!--     <geom type="capsule" fromto="0 0 0 0 0 0.8" size="0.02" rgba="0.2 0.6 0.8 1"/> -->
    <!--   </body> -->
    <!-- </body> -->
  </worldbody>

  <actuator>
    <motor joint="hinge1" ctrlrange="-45 45" gear="1"/>
  </actuator>

</mujoco>
